<mujoco model="oswald">
<compiler inertiafromgeom="true" angle="degree" coordinates="global" />
<worldbody>
<body name="body" pos="0.0 0.0 1.0">
<joint name="fixedboi" type="fixed" />
<geom name="body" type="box" pos="0 0 0" size="0.075 0.1 0.09" />
<body name="left_recip" pos="0 0 0">
<geom name="left_recip" type="capsule" fromto="-0.014999999999999993 0.1125 -0.016199999999999992 0.006001000000000006 0.1125 -0.04798999999999998" size="0.0075" />
<joint name="left_recip_mount" type="hinge" pos="-0.014999999999999993 0.0 -0.016199999999999992" axis="0 1 0" />
<body name="left_connector" pos="0 0 0">
<geom name="left_connector" type="capsule" fromto="0.006001000000000006 0.1315 -0.04798999999999998 0.075897 0.1315 -0.0017260000000000053" size="0.0075" />
<joint name="left_recip_connector" type="hinge" pos="0.006001000000000006 0.0 -0.04798999999999998" axis="0 1 0" />
<body name="left_thigh" pos="0 0 0">
<geom name="left_thigh" type="capsule" fromto="0.010400000000000006 0.1115 0.06000000000000005 0.13055100000000003 0.1115 -0.053233000000000086" size="0.0075" />
<joint name="left_recip_connector_joint" type="hinge" pos="0.075897 0.0 -0.0017260000000000053" axis="0 1 0" />
<body name="left_shin" pos="0 0 0">
<geom name="left_shin" type="capsule" fromto="0.13055100000000003 0.1295 -0.053233000000000086 0.07589 0.1295 -0.22242300000000004" size="0.0075" />
<joint name="left_thigh_shin" type="hinge" pos="0.13055100000000003 0.0 -0.053233000000000086" axis="0 1 0" />
<body name="left_shin_dummy" pos="0.13055100000000003 0.1295 -0.053233000000000086" />
</body>
<body name="left_4bar" pos="0 0 0">
<geom name="left_4bar" type="capsule" fromto="0.10282400000000001 0.1295 -0.02710199999999996 0.04816300000000001 0.1295 -0.19629200000000002" size="0.0075" />
<joint name="left_thigh_4bar" type="hinge" pos="0.10282400000000001 0.0 -0.02710199999999996" axis="0 1 0" />
<body name="left_4bar_dummy" pos="0.10282400000000001 0.1295 -0.02710199999999996" />
</body>
<body name="left_body_thigh_dummy2" pos="0.010400000000000006 0.1115 0.06000000000000005" />
</body>
</body>
<body name="left_recip_dummy" pos="0.006001000000000006 0.1125 -0.04798999999999998" />
</body>
<body name="left_body_thigh_dummy1" pos="0.010400000000000006 0.1115 0.06000000000000005" />
</body>
</worldbody>
</mujoco>
